Workbook

Sheet Total 2024
A1: -+ | B1: Despesas | C1: Receita | D1: Saldo | F1: Despesa Total 2024 | G1: Receita Total 2024 | H1: Saldo Total 2024
A2: Março | B2: =('Março'!E1) -> 1962.12 | C2: 2162 | D2: =C2-B2 -> 199.88 | F2: =SUM(B2:B11) -> 14220.44 | G2: =SUM(C2:C11) -> 19693 | H2: =SUM(D2:D11) -> 5472.56
A3: Abril | B3: =(Abril!E1) -> 1676.33 | C3: 1876 | D3: =C3-B3 -> 199.67
A4: Maio | B4: =(Maio!E1) -> 1305.83 | C4: 1505 | D4: =C4-B4 -> 199.17
A5: Junho | B5: =(Junho!E1) -> 1372 | C5: 1572 | D5: =C5-B5 -> 200
A6: Julho | B6: =(Julho!E1) -> 1330.9 | C6: 1830 | D6: =C6-B6 -> 499.1
A7: Agosto | B7: =(Agosto!E1) -> 1355.3 | C7: 1555 | D7: =C7-B7 -> 199.7
A8: Setembro | B8: =(Setembro!F2) -> 1213.5 | C8: =(Setembro!G2) -> 1661 | D8: =C8-B8 -> 447.5
A9: Outubro | B9: =(Outubro!F2) -> 1427 | C9: =(Outubro!G2) -> 1979 | D9: =C9-B9 -> 552
A10: Novembro | B10: =(Novembro!F2) -> 1080.34 | C10: =(Novembro!G2) -> 2859 | D10: =C10-B10 -> 1778.66
A11: Dezembro | B11: =(Dezembro!F2) -> 1497.12 | C11: =(Dezembro!G2) -> 2694 | D11: =C11-B11 -> 1196.88

Sheet Março
A1: 45352 | B1: sexta-feira | C1: 5.5 | D1: Açucar, Pão de queijo | E1: =SUM(C1:C31) -> 1962.12
A2: 45353 | B2: sábado | C2: 0 | D2: None
A3: 45354 | B3: domingo | C3: 18.88 | D3: Sorvete
A4: 45355 | B4: segunda-feira | C4: 4.5 | D4: Caldo de cana
A5: 45356 | B5: terça-feira | C5: 0
A6: 45357 | B6: quarta-feira | C6: 0
A7: 45358 | B7: quinta-feira | C7: 7 | D7: Salgado e suco
A8: 45359 | B8: sexta-feira | C8: 200 | D8: Mãe
A9: 45360 | B9: sábado | C9: 30.1 | D9: Táxi, almoço
A10: 45361 | B10: domingo | C10: 30 | D10: Internet
A11: 45362 | B11: segunda-feira | C11: 4.5 | D11: Caldo de cana
A12: 45363 | B12: terça-feira | C12: 846 | D12: Guarda chuva (23) + auto escola
A13: 45364 | B13: quarta-feira | C13: 0
A14: 45365 | B14: quinta-feira | C14: 100 | D14: Mãe
A15: 45366 | B15: sexta-feira | C15: 0
A16: 45367 | B16: sábado | C16: 16 | D16: Salgados e refrigerante
A17: 45368 | B17: domingo | C17: 15.75 | D17: sorvete
A18: 45369 | B18: segunda-feira | C18: 20 | D18: almoço
A19: 45370 | B19: terça-feira | C19: 159.25 | D19: Mãe e Lanche
A20: 45371 | B20: quarta-feira | C20: 75.99 | D20: Lanche (16) e Camisa Elegance (59,99)
A21: 45372 | B21: quinta-feira | C21: 4.5 | D21: Caldo de cana
A22: 45373 | B22: sexta-feira | C22: 7 | D22: Pão de queijo e caldo de cana
A23: 45374 | B23: sábado | C23: 74.5 | D23: Presente da fernanda, Caldo de cana, Participação no salgado da Moda Show e Mãe
A24: 45375 | B24: domingo | C24: 28 | D24: Milkshake
A25: 45376 | B25: segunda-feira | C25: 24.5 | D25: Lanches diversos dias
A26: 45377 | B26: terça-feira | C26: 30 | D26: Internet
A27: 45378 | B27: quarta-feira | C27: 0
A28: 45379 | B28: quinta-feira | C28: 0
A29: 45380 | B29: sexta-feira | C29: 58.7 | D29: Sorvete + Brawn stars pass
A30: 45381 | B30: sábado | C30: 153 | D30: Caixa de bombom + Sprite (16) + almoço (27) + uber (10) + Mãe (100)
A31: 45382 | B31: domingo | C31: 48.45 | D31: refrigerante e sorvete

Sheet Abril
A1: 45383 | B1: segunda-feira | C1: 0 | E1: =SUM(C1:C31) -> 1676.33
A2: 45384 | B2: terça-feira | C2: 0
A3: 45385 | B3: quarta-feira | C3: 7.5 | D3: Caldo de cana e chokito
A4: 45386 | B4: quinta-feira | C4: 39.9 | D4: Brawn stars
A5: 45387 | B5: sexta-feira | C5: 28 | D5: Pizza a noite
A6: 45388 | B6: sábado | C6: 310.09 | D6: Calça Teezz (85,99), Uber moto (20), Saida a noite (144,10) uber (30), Mãe (30)
A7: 45389 | B7: domingo | C7: 21.74 | D7: Sorvete
A8: 45390 | B8: segunda-feira | C8: 0
A9: 45391 | B9: terça-feira | C9: 42 | D9: presente aniversário Gustavo
A10: 45392 | B10: quarta-feira | C10: 25 | D10: Guarda chuva pra mãe
A11: 45393 | B11: quinta-feira | C11: 100 | D11: presente aniversário Sheila (Março)
A12: 45394 | B12: sexta-feira | C12: 130 | D12: Maquina de barbear
A13: 45395 | B13: sábado | C13: 80 | D13: Uber ida e volta, milkshake, pass brawn stars (gustavo)
A14: 45396 | B14: domingo | C14: 330 | D14: Auto Escola
A15: 45397 | B15: segunda-feira | C15: 145 | D15: Mãe (130), Lanches
A16: 45398 | B16: terça-feira | C16: 153.5 | D16: Mãe (150), suco
A17: 45399 | B17: quarta-feira | C17: 0
A18: 45400 | B18: quinta-feira | C18: 0
A19: 45401 | B19: sexta-feira | C19: 44.6 | D19: Mãe (15), lanches diversos dias
A20: 45402 | B20: sábado | C20: 10 | D20: Mãe
A21: 45403 | B21: domingo | C21: 36 | D21: Sorvete
A22: 45404 | B22: segunda-feira | C22: 63.5 | D22: Cuecas e Suco (3,50)
A23: 45405 | B23: terça-feira | C23: 9.5 | D23: Caldo de cana e salgado
A24: 45406 | B24: quarta-feira | C24: 0
A25: 45407 | B25: quinta-feira | C25: 0
A26: 45408 | B26: sexta-feira | C26: 0
A27: 45409 | B27: sábado | C27: 0
A28: 45410 | B28: domingo | C28: 70 | D28: Minas shopping
A29: 45411 | B29: segunda-feira | C29: 0
A30: 45412 | B30: terça-feira | C30: 30 | D30: Almoço

Sheet Maio
A1: 45413 | B1: quarta-feira | E1: =SUM(C1:C31) -> 1305.83
A2: 45414 | B2: quinta-feira
A3: 45415 | B3: sexta-feira | C3: 331 | D3: 225 reconhecimento de pista, 100 Mãe, 6 refrigerante
A4: 45416 | B4: sábado | C4: 3.8 | D4: Limonada
A5: 45417 | B5: domingo
A6: 45418 | B6: segunda-feira | C6: 16.55 | D6: lanches em geral
A7: 45419 | B7: terça-feira
A8: 45420 | B8: quarta-feira | C8: 113.8 | D8: Auto Escola (13), presente dia das mães (85), sorvete (12), Suco (3,80)
A9: 45421 | B9: quinta-feira
A10: 45422 | B10: sexta-feira
A11: 45423 | B11: sábado | C11: 60 | D11: Celeste
A12: 45424 | B12: domingo | C12: 57 | D12: Sorvete, Chocolate, gastos em geral
A13: 45425 | B13: segunda-feira
A14: 45426 | B14: terça-feira
A15: 45427 | B15: quarta-feira
A16: 45428 | B16: quinta-feira | C16: 117.45 | D16: Mãe (100), Lanches gerais
A17: 45429 | B17: sexta-feira
A18: 45430 | B18: sábado
A19: 45431 | B19: domingo | C19: 214 | D19: Mãe (200), Milk shake
A20: 45432 | B20: segunda-feira
A21: 45433 | B21: terça-feira
A22: 45434 | B22: quarta-feira | C22: 7.3 | D22: Caldo de Cana e Chokito
A23: 45435 | B23: quinta-feira
A24: 45436 | B24: sexta-feira | C24: 67.6 | D24: Café da manhã, lanche e mãe (50)
A25: 45437 | B25: sábado
A26: 45438 | B26: domingo | C26: 70.45 | D26: Sorvete, Mãe (50)
A27: 45439 | B27: segunda-feira
A28: 45440 | B28: terça-feira | C28: 59.74 | D28: Creme para pentear, desodorante (54,98), trento (4,76)
A29: 45441 | B29: quarta-feira | C29: 27.5 | D29: Sprite, Mãe (20)
A30: 45442 | B30: quinta-feira | C30: 26.65 | D30: Sorvete
A31: 45443 | B31: sexta-feira | C31: 132.99 | D31: Mãe, Calça Teezz (85,99)

Sheet Junho
A1: 45444 | B1: sábado | C1: 38 | D1: Presente aniversário luna | E1: =SUM(C1:C31) -> 1372
A2: 45445 | B2: domingo | C2: 270 | D2: Cadeira
A3: 45446 | B3: segunda-feira
A4: 45447 | B4: terça-feira
A5: 45448 | B5: quarta-feira | C5: 500 | D5: Aluguel
A6: 45449 | B6: quinta-feira | C6: 7 | D6: Trento e Chokito
A7: 45450 | B7: sexta-feira
A8: 45451 | B8: sábado
A9: 45452 | B9: domingo | C9: 20 | D9: Macarrão na Chapa
A10: 45453 | B10: segunda-feira | C10: 50 | D10: Tinta da calça
A11: 45454 | B11: terça-feira | C11: 3.8 | D11: Suco almoço
A12: 45455 | B12: quarta-feira
A13: 45456 | B13: quinta-feira
A14: 45457 | B14: sexta-feira
A15: 45458 | B15: sábado | C15: 28 | D15: sorvete, cappucino, pão de queijo
A16: 45459 | B16: domingo | C16: 28 | D16: pão de queijo, refrigerante, pão de mel
A17: 45460 | B17: segunda-feira | C17: 65 | D17: sorvete, Mãe (20)
A18: 45461 | B18: terça-feira | C18: 50 | D18: Garrafas (20), Mãe (30)
A19: 45462 | B19: quarta-feira
A20: 45463 | B20: quinta-feira
A21: 45464 | B21: sexta-feira | C21: 100 | D21: Mãe
A22: 45465 | B22: sábado | C22: 62 | D22: Ida no nazaré, The Coffin of Andy and Leyley (32)
A23: 45466 | B23: domingo | C23: 20 | D23: Sorvete
A24: 45467 | B24: segunda-feira
A25: 45468 | B25: terça-feira
A26: 45469 | B26: quarta-feira
A27: 45470 | B27: quinta-feira
A28: 45471 | B28: sexta-feira
A29: 45472 | B29: sábado | C29: 16.2 | D29: Lanches diversos dias
A30: 45473 | B30: domingo | C30: 114 | D30: Sorvete e refrigerante (27), Mãe (50), Sorvete noite + mãe (37)

Sheet Julho
A1: 45474 | B1: segunda-feira | C1: 50 | D1: Mãe (50) | E1: =SUM(C1:C31) -> 1330.9
A2: 45475 | B2: terça-feira | C2: 25.5 | D2: Caldo de Cana, Hollow Knight
A3: 45476 | B3: quarta-feira
A4: 45477 | B4: quinta-feira | C4: 57 | D4: Brawn Stars, aniversário nilcea, salgado
A5: 45478 | B5: sexta-feira | C5: 500 | D5: Aluguel
A6: 45479 | B6: sábado | C6: 40 | D6: Uber ida e volta
A7: 45480 | B7: domingo
A8: 45481 | B8: segunda-feira | C8: 50 | D8: Mãe
A9: 45482 | B9: terça-feira | C9: 25 | D9: Desodorante, Pasta de Dente, Suco (3,80)
A10: 45483 | B10: quarta-feira
A11: 45484 | B11: quinta-feira
A12: 45485 | B12: sexta-feira
A13: 45486 | B13: sábado
A14: 45487 | B14: domingo
A15: 45488 | B15: segunda-feira | C15: 113 | D15: Calças chimpa e gastos diversos
A16: 45489 | B16: terça-feira
A17: 45490 | B17: quarta-feira
A18: 45491 | B18: quinta-feira
A19: 45492 | B19: sexta-feira | C19: 50.5 | D19: 17,50 (Enrolado e refrigerante) + 34 (Sanduiche)
A20: 45493 | B20: sábado | C20: 28.5 | D20: 15 (Metade da internet mãe) + 10 (Mãe) + 3,50 (Refrigerante)
A21: 45494 | B21: domingo | C21: 83.8 | D21: 3,80 (Suco) + 24 (Uber Volta) + 26 (despedida walquiria) + 30 (internet)
A22: 45495 | B22: segunda-feira | C22: 135 | D22: Mãe (100), Relaxante de cabelo (30), Salgado (5)
A23: 45496 | B23: terça-feira
A24: 45497 | B24: quarta-feira
A25: 45498 | B25: quinta-feira
A26: 45499 | B26: sexta-feira
A27: 45500 | B27: sábado
A28: 45501 | B28: domingo
A29: 45502 | B29: segunda-feira
A30: 45503 | B30: terça-feira | C30: 172.6 | D30: Ida no Cinema, Almoço 2 dias e Mãe
A31: 45504 | B31: quarta-feira

Sheet Agosto
A1: 45505 | B1: quinta-feira | E1: =SUM(C1:C31) -> 1355.3
A2: 45506 | B2: sexta-feira
A3: 45507 | B3: sábado
A4: 45508 | B4: domingo
A5: 45509 | B5: segunda-feira | C5: 500 | D5: Aluguel
A6: 45510 | B6: terça-feira | C6: 190.8 | D6: Internet (30), Sorvete (15), Suco (3,80), 142 (Geladeira)
A7: 45511 | B7: quarta-feira
A8: 45512 | B8: quinta-feira
A9: 45513 | B9: sexta-feira | C9: 32 | D9: Passagem, Cartão de passagem
A10: 45514 | B10: sábado | C10: 9.5 | D10: Doce, Refrigerante
A11: 45515 | B11: domingo | C11: 19 | D11: Sorvete
A12: 45516 | B12: segunda-feira
A13: 45517 | B13: terça-feira
A14: 45518 | B14: quarta-feira
A15: 45519 | B15: quinta-feira | C15: 80 | D15: Mãe
A16: 45520 | B16: sexta-feira | C16: 28 | D16: Sorvete
A17: 45521 | B17: sábado | C17: 75 | D17: Presente Victória, Corte de cabelo
A18: 45522 | B18: domingo | C18: 50 | D18: Mãe
A19: 45523 | B19: segunda-feira | C19: 132 | D19: Macarrão na Chapa, Mãe Uber Natale (90)
A20: 45524 | B20: terça-feira | C20: 28 | D20: Almoço
A21: 45525 | B21: quarta-feira | C21: 51 | D21: Lanche a noite
A22: 45526 | B22: quinta-feira
A23: 45527 | B23: sexta-feira
A24: 45528 | B24: sábado
A25: 45529 | B25: domingo
A26: 45530 | B26: segunda-feira
A27: 45531 | B27: terça-feira
A28: 45532 | B28: quarta-feira
A29: 45533 | B29: quinta-feira
A30: 45534 | B30: sexta-feira
A31: 45535 | B31: sábado | C31: 160 | D31: Suposição de gastos

Sheet Setembro
A1: Dia do Mês | B1: Dia da Semana | C1: Despesas | D1: Receitas | E1: Informação adicional | F1: Valor Gasto | G1: Valor Faturado | H1: Saldo
A2: 45536 | B2: domingo | F2: =SUM(C2:C31) -> 1213.5 | G2: =SUM(D2:D31) -> 1661 | H2: =G2-F2 -> 447.5
A3: 45537 | B3: segunda-feira | C3: 28 | E3: Almoço
A4: 45538 | B4: terça-feira | D4: 969 | E4: Salário
A5: 45539 | B5: quarta-feira
A6: 45540 | B6: quinta-feira | C6: 500 | E6: Aluguel
A7: 45541 | B7: sexta-feira | C7: 20 | E7: Pastel
A8: 45542 | B8: sábado | C8: 20 | D8: 20 | E8: Sorvete / Bonificação
A9: 45543 | B9: domingo | C9: 20 | E9: Sorvete
A10: 45544 | B10: segunda-feira
A11: 45545 | B11: terça-feira
A12: 45546 | B12: quarta-feira | C12: 100 | E12: Sheila
A13: 45547 | B13: quinta-feira | C13: 150 | E13: Guarda roupa
A14: 45548 | B14: sexta-feira | C14: 109 | E14: Geladeira
A15: 45549 | B15: sábado | D15: 20 | E15: Bonificação
A16: 45550 | B16: domingo
A17: 45551 | B17: segunda-feira
A18: 45552 | B18: terça-feira
A19: 45553 | B19: quarta-feira | D19: 632 | E19: (Adiantamento)
A20: 45554 | B20: quinta-feira
A21: 45555 | B21: sexta-feira
A22: 45556 | B22: sábado | C22: 88 | D22: 20 | E22: Lanche (50) + camisa UV (38) / Bonificação
A23: 45557 | B23: domingo | C23: 14 | E23: Sorvete
A24: 45558 | B24: segunda-feira
A25: 45559 | B25: terça-feira
A26: 45560 | B26: quarta-feira
A27: 45561 | B27: quinta-feira | C27: 30 | E27: Mãe
A28: 45562 | B28: sexta-feira | C28: 13.5 | E28: Paçoca, Pastel e Suco em dias diversos
A29: 45563 | B29: sábado | C29: 57 | E29: Almoço restaurante (27), Internet (30)
A30: 45564 | B30: domingo | C30: 14 | E30: Milkshake
A31: 45565 | B31: segunda-feira | C31: 50 | E31: Mãe

Sheet Outubro
A1: Dia do Mês | B1: Dia da Semana | C1: Despesas | D1: Receita | E1: Informação adicional | F1: Despesas | G1: Receita | H1: Saldo
A2: 45566 | B2: Terça-feira | C2: 0 | D2: 0 | F2: =SUM(C2:C32) -> 1427 | G2: =SUM(D2:D32) -> 1979 | H2: =G2-F2 -> 552
A3: 45567 | B3: quarta-feira | C3: 68 | E3: Camisa Uv Azul, Internet
A4: 45568 | B4: quinta-feira | D4: 1077 | E4: Salário
A5: 45569 | B5: sexta-feira | D5: 150 | E5: Remuneração Estoque
A6: 45570 | B6: sábado | C6: 528 | D6: 20 | E6: Aluguel, Almoço / Bonificação
A7: 45571 | B7: domingo | C7: 49 | E7: Sanduiche, Sorvete
A8: 45572 | B8: segunda-feira | C8: 25 | E8: 3 Pastas de Dente, Vitamina
A9: 45573 | B9: terça-feira
A10: 45574 | B10: quarta-feira
A11: 45575 | B11: quinta-feira | C11: 270 | E11: Transporte Geladeira Mãe (250) ; Edmar (20)
A12: 45576 | B12: sexta-feira | D12: 40 | E12: Edmar (20) / Bonificação
A13: 45577 | B13: sábado
A14: 45578 | B14: domingo | C14: 21 | E14: Sorvete
A15: 45579 | B15: segunda-feira | C15: 200 | E15: Mãe
A16: 45580 | B16: terça-feira | C16: 9 | E16: Refrigerante (7,50), caneta (1,50)
A17: 45581 | B17: quarta-feira | C17: 0
A18: 45582 | B18: quinta-feira | D18: 632 | E18: Adiantamento
A19: 45583 | B19: sexta-feira | C19: 9.5 | E19: Suco, Refrigerante
A20: 45584 | B20: sábado | C20: 40.5 | D20: 20 | E20: Doces, Sanduiche / Bonificação
A21: 45585 | B21: domingo | C21: 20 | D21: 10 | E21: Crunchyroll / Gustavo Crunchyroll
A22: 45586 | B22: segunda-feira | C22: 4 | E22: Suco
A23: 45587 | B23: terça-feira | C23: 86 | E23: Geladeira
A24: 45588 | B24: quarta-feira
A25: 45589 | B25: quinta-feira
A26: 45590 | B26: sexta-feira
A27: 45591 | B27: sábado | C27: 61.5 | D27: 20 | E27: Cachorro quente (ingredientes) / Bonificação
A28: 45592 | B28: domingo | C28: 22 | E28: Sorvete
A29: 45593 | B29: segunda-feira
A30: 45594 | B30: terça-feira | C30: 9.5 | E30: Lanche
A31: 45595 | B31: quarta-feira | C31: 4 | D31: 10 | E31: Lanche, Caneta p - vitória / Bonificação
A32: 45596 | B32: quinta-feira

Sheet Novembro
A1: Dia do Mês | B1: Dia da Semana | C1: Despesas | D1: Receitas | E1: Informação adicional | F1: Valor Gasto | G1: Valor Faturado | H1: Saldo
A2: 45597 | B2: Sexta-Feira | C2: 22 | D2: 20 | E2: Supermercado / Bonificação | F2: =SUM(C2:C31) -> 1080.34 | G2: =SUM(D2:D31) -> 2859 | H2: =G2-F2 -> 1778.66
A3: 45598 | B3: sábado | C3: 21 | E3: Sorvete
A4: 45599 | B4: domingo
A5: 45600 | B5: segunda-feira | C5: 31 | E5: Corte de Cabelo
A6: 45601 | B6: terça-feira | C6: 500 | D6: 150 | E6: Aluguel / Remuneração Estoque
A7: 45602 | B7: quarta-feira | C7: 5 | D7: 1219 | E7: Bolo / Salário
A8: 45603 | B8: quinta-feira
A9: 45604 | B9: sexta-feira
A10: 45605 | B10: sábado | D10: 20 | E10: Bonificação
A11: 45606 | B11: domingo | C11: 25 | E11: Sorvete
A12: 45607 | B12: segunda-feira | C12: 132 | E12: Ventilador aniversário Mãe
A13: 45608 | B13: terça-feira | C13: 30 | E13: Internet
A14: 45609 | B14: quarta-feira | C14: 90 | D14: 632 | E14: Calça / Adiantamento
A15: 45610 | B15: quinta-feira | C15: 2.5 | E15: Pão de queijo
A16: 45611 | B16: sexta-feira | C16: 10.63 | E16: Uber
A17: 45612 | B17: sábado | D17: 20 | E17: Bonificação
A18: 45613 | B18: domingo | C18: 36 | E18: Sorvete
A19: 45614 | B19: segunda-feira
A20: 45615 | B20: terça-feira | C20: 30.34 | E20: Supermercado
A21: 45616 | B21: quarta-feira | C21: 20 | E21: Crunchyroll
A22: 45617 | B22: quinta-feira
A23: 45618 | B23: sexta-feira
A24: 45619 | B24: sábado | C24: 15.5 | D24: 20 | E24: Mãe (10), Refrigerante / Bonificação
A25: 45620 | B25: domingo | C25: 13.37 | E25: Refrigerante nataly
A26: 45621 | B26: segunda-feira | D26: 778 | E26: 13° salário
A27: 45622 | B27: terça-feira | C27: 96 | E27: Fone, Internet (30), Milshake (26)
A28: 45623 | B28: quarta-feira
A29: 45624 | B29: quinta-feira
A30: 45625 | B30: sexta-feira
A31: 45626 | B31: sábado

Sheet Dezembro
A1: Dia do Mês | B1: Dia da Semana | C1: Despesas | D1: Receitas | E1: Informação adicional | F1: Valor Gasto | G1: Valor Faturado | H1: Saldo
A2: 45627 | B2: Domingo | C2: 127.59 | D2: 0 | E2: Rodízio | F2: =SUM(C2:C31) -> 1497.12 | G2: =SUM(D2:D31) -> 2694 | H2: =G2-F2 -> 1196.88
A3: 45628 | B3: segunda-feira | D3: 1102 | E3: Salário + Bonificação (20)
A4: 45629 | B4: terça-feira
A5: 45630 | B5: quarta-feira
A6: 45631 | B6: quinta-feira | C6: 500 | D6: 150 | E6: Aluguel / Remuneração estoque
A7: 45632 | B7: sexta-feira
A8: 45633 | B8: sábado | C8: 8 | D8: 20 | E8: Lanche / Bonificação (20)
A9: 45634 | B9: domingo
A10: 45635 | B10: segunda-feira | C10: 288.53 | E10: Geladeira, Guarda Roupa, Produtos Rede
A11: 45636 | B11: terça-feira | C11: 8 | E11: Lanche
A12: 45637 | B12: quarta-feira | C12: 23 | D12: 632 | E12: Sorvete / Adiantamento
A13: 45638 | B13: quinta-feira
A14: 45639 | B14: sexta-feira | D14: 20 | E14: Crunchyroll Gustavo
A15: 45640 | B15: sábado | C15: 100 | D15: 20 | E15: Mãe / Bonificação
A16: 45641 | B16: domingo
A17: 45642 | B17: segunda-feira
A18: 45643 | B18: terça-feira
A19: 45644 | B19: quarta-feira
A20: 45645 | B20: quinta-feira
A21: 45646 | B21: sexta-feira | D21: 730 | E21: 13° salário
A22: 45647 | B22: sábado | D22: 20 | E22: Bonificação
A23: 45648 | B23: domingo
A24: 45649 | B24: segunda-feira | C24: 100 | E24: toalha
A25: 45650 | B25: terça-feira | C25: 11 | E25: Lanche
A26: 45651 | B26: quarta-feira
A27: 45652 | B27: quinta-feira | C27: 20 | E27: Crunchyroll
A28: 45653 | B28: sexta-feira | C28: 11 | E28: Lanche
A29: 45654 | B29: sábado | C29: 120 | E29: Mãe (100), jogo mãe
A30: 45655 | B30: domingo | C30: 180 | E30: Kit Churrasco
A31: 45656 | B31: segunda-feira
A32: 45657 | B32: terça-feira

Sheet Total 2025
A1: Janeiro | B1: Pix | C1: Dinheiro F | D1: Cartão | E1: Total | F1: Saldo | H1: Despesa Total 2025 | I1: Receita Total 2025 | J1: Saldo Total 2025
A2: Despesa | B2: =('Janeiro 2025'!H8) -> 1051.37 | C2: =('Janeiro 2025'!I8) -> 325.9 | D2: =('Janeiro 2025'!J8) -> 113.1 | E2: ='Janeiro 2025'!K8 -> 1490.37 | F2: =E3-E2 -> 597.63 | H2: =SUMIF(A2:A46,"Despesa",E2:E46) -> 24611.38 | I2: =SUMIF(A2:A46,"Receita",E2:E46) -> 34480.99 | J2: =SUM(F2:F46) -> 10769.61
A3: Receita | B3: =('Janeiro 2025'!H9) -> 1823 | C3: =('Janeiro 2025'!I9) -> 190 | D3: =('Janeiro 2025'!J9) -> 75 | E3: ='Janeiro 2025'!K9 -> 2088
A5: Fevereiro | B5: Pix | C5: Dinheiro F | D5: Cartão | E5: Total | F5: Saldo
A6: Despesa | B6: =('Fevereiro 2025'!H8) -> 932 | C6: =('Fevereiro 2025'!I8) -> 300.1 | D6: =('Fevereiro 2025'!J8) -> 581.79 | E6: ='Fevereiro 2025'!K8 -> 1813.89 | F6: =E7-E6 -> 4408.11
A7: Receita | B7: =('Fevereiro 2025'!H9) -> 4000 | C7: =('Fevereiro 2025'!I9) -> 330 | D7: =('Fevereiro 2025'!J9) -> 1892 | E7: ='Fevereiro 2025'!K9 -> 6222
A9: Março | B9: Pix | C9: Dinheiro F | D9: Cartão | E9: Total | F9: Saldo
A10: Despesa | B10: =('Março 2025'!H8) -> 952.73 | C10: =('Março 2025'!I8) -> 186 | D10: =('Março 2025'!J8) -> 676.31 | E10: ='Março 2025'!K8 -> 1815.04 | F10: =E11-E10 -> 817.96
A11: Receita | B11: =('Março 2025'!H9) -> 22 | C11: =('Março 2025'!I9) -> 230 | D11: =('Março 2025'!J9) -> 2381 | E11: ='Março 2025'!K9 -> 2633
A13: Abril | B13: Pix | C13: Dinheiro F | D13: Cartão | E13: Total | F13: Saldo
A14: Despesa | B14: =('Abril 2025'!H8) -> 832.98 | C14: =('Abril 2025'!I8) -> 88 | D14: =('Abril 2025'!J8) -> 444.35 | E14: ='Abril 2025'!K8 -> 1365.33 | F14: =E15-E14 -> 1148.67
A15: Receita | B15: =('Abril 2025'!H9) -> 150 | C15: =('Abril 2025'!I9) -> 230 | D15: =('Abril 2025'!J9) -> 2134 | E15: ='Abril 2025'!K9 -> 2514
A17: Maio | B17: Pix | C17: Dinheiro F | D17: Cartão | E17: Total | F17: Saldo
A18: Despesa | B18: =('Maio 2025'!H8) -> 1242.97 | C18: =('Maio 2025'!I8) -> 274.65 | D18: =('Maio 2025'!J8) -> 137.5 | E18: ='Maio 2025'!K8 -> 1655.12 | F18: =E19-E18 -> 673.88
A19: Receita | B19: =('Maio 2025'!H9) -> 0 | C19: =('Maio 2025'!I9) -> 230 | D19: =('Maio 2025'!J9) -> 2099 | E19: ='Maio 2025'!K9 -> 2329
A21: Junho | B21: Pix | C21: Dinheiro F | D21: Cartão | E21: Total | F21: Saldo
A22: Despesa | B22: =('Junho 2025'!H8) -> 4261.98 | C22: =('Junho 2025'!I8) -> 151 | D22: =('Junho 2025'!J8) -> 227.93 | E22: ='Junho 2025'!K8 -> 4640.91 | F22: =E23-E22 -> -2273.91
A23: Receita | B23: =('Junho 2025'!H9) -> 0 | C23: =('Junho 2025'!I9) -> 330 | D23: =('Junho 2025'!J9) -> 2037 | E23: ='Junho 2025'!K9 -> 2367
A25: Julho | B25: Pix | C25: Dinheiro F | D25: Cartão | E25: Total | F25: Saldo
A26: Despesa | B26: =('Julho 2025'!H8) -> 980.15 | C26: =('Julho 2025'!I8) -> 0 | D26: =('Julho 2025'!J8) -> 149.7 | E26: ='Julho 2025'!K8 -> 1129.85 | F26: =E27-E26 -> 8332.94
A27: Receita | B27: =('Julho 2025'!H9) -> 0 | C27: =('Julho 2025'!I9) -> 100 | D27: =('Julho 2025'!J9) -> 9362.79 | E27: ='Julho 2025'!K9 -> 9462.79
A29: Agosto | B29: Pix | C29: Dinheiro F | D29: Cartão | E29: Total | F29: Saldo
A30: Despesa | B30: =('Agosto 2025'!H8) -> 2337.82 | C30: =('Agosto 2025'!I8) -> 68 | D30: =('Agosto 2025'!J8) -> 0 | E30: ='Agosto 2025'!K8 -> 2405.82 | F30: =E31-E30 -> -525.82
A31: Receita | B31: =('Agosto 2025'!H9) -> 0 | C31: =('Agosto 2025'!I9) -> 1880 | D31: =('Agosto 2025'!J9) -> 0 | E31: ='Agosto 2025'!K9 -> 1880
A33: Setembro | B33: Pix | C33: Dinheiro F | D33: Cartão | E33: Total | F33: Saldo
A34: Despesa | B34: =('Setembro 2025'!H8) -> 1472.18 | C34: =('Setembro 2025'!I8) -> 0 | D34: =('Setembro 2025'!J8) -> 240.54 | E34: ='Setembro 2025'!K8 -> 1712.72 | F34: =E35-E34 -> 282.88
A35: Receita | B35: =('Setembro 2025'!H9) -> 50 | C35: =('Setembro 2025'!I9) -> 111.6 | D35: =('Setembro 2025'!J9) -> 1834 | E35: ='Setembro 2025'!K9 -> 1995.6
A37: Outubro | B37: Pix | C37: Dinheiro F | D37: Cartão | E37: Total | F37: Saldo
A38: Despesa | B38: =('Outubro 2025'!H8) -> 2271.3 | C38: =('Outubro 2025'!I8) -> 12 | D38: =('Outubro 2025'!J8) -> 418.56 | E38: =('Outubro 2025'!K8) -> 2701.86 | F38: =E39-E38 -> -723.86
A39: Receita | B39: =('Outubro 2025'!H9) -> 144 | C39: =('Outubro 2025'!I9) -> 0 | D39: =('Outubro 2025'!J9) -> 1834 | E39: =('Outubro 2025'!K9) -> 1978
A41: Novembro | B41: Pix | C41: Dinheiro F | D41: Cartão | E41: Total | F41: Saldo
A42: Despesa | B42: =('Novembro 2025'!H8) -> 1366.41 | C42: =('Novembro 2025'!I8) -> 0 | D42: =('Novembro 2025'!J8) -> 689.13 | E42: =('Novembro 2025'!K8) -> 2055.54 | F42: =E43-E42 -> -1043.94
A43: Receita | B43: =('Novembro 2025'!H9) -> 900 | C43: =('Novembro 2025'!I9) -> 111.6 | D43: =('Novembro 2025'!J9) -> 0 | E43: =('Novembro 2025'!K9) -> 1011.6
A45: Dezembro | B45: Pix | C45: Dinheiro F | D45: Cartão | E45: Total | F45: Saldo
A46: Despesa | B46: =('Dezembro 2025'!H8) -> 1764.07 | C46: =('Dezembro 2025'!I8) -> 0 | D46: =('Dezembro 2025'!J8) -> 60.86 | E46: =('Dezembro 2025'!K8) -> 1824.93 | F46: =E47-E46 -> -924.93
A47: Receita | B47: =('Dezembro 2025'!H9) -> 900 | C47: =('Dezembro 2025'!I9) -> 0 | D47: =('Dezembro 2025'!J9) -> 0 | E47: =('Dezembro 2025'!K9) -> 900

Sheet Janeiro 2026
A6: Semana 1 | J6: Semana 2
A7: Janeiro | J7: Janeiro
A8: 46023 | B8: - | C8: - | D8: - | E8: - | F8: - | G8: - | H8: Saldo da semana | J8: 46030 | K8: - | L8: - | M8: - | N8: - | O8: - | P8: - | Q8: Saldo da semana | S8: =SUM(B8:D14) -> 467.82 | T8: =SUM(E8:G14) -> 0
A9: 46024 | B9: - | C9: - | D9: - | E9: - | F9: - | G9: - | H9: =T8-S8 -> -467.82 | J9: 46031 | K9: - | L9: - | M9: - | N9: - | O9: - | P9: - | Q9: =T9-S9 -> -441.98 | S9: =SUM(K8:M14) -> 441.98 | T9: =sum(N8:P14) -> 0
A10: 46025 | B10: 22.1 | C10: 34.9 | D10: 26.1 | E10: - | F10: - | G10: - | J10: 46032 | K10: - | L10: - | M10: - | N10: - | O10: - | P10: - | S10: =sum(B18:D24) -> 1147.06 | T10: =sum(E18:G24) -> 100
A11: 46026 | B11: - | C11: - | D11: - | E11: - | F11: - | G11: - | J11: 46033 | K11: - | L11: - | M11: - | N11: - | O11: - | P11: - | S11: =sum(K18:M24) -> 0 | T11: =sum(N18:P24) -> 0
A12: 46027 | B12: - | C12: - | D12: - | E12: - | F12: - | G12: - | J12: 46034 | K12: 340 | L12: - | M12: - | N12: - | O12: - | P12: - | S12: =sum(B29:D31) -> 32.35 | T12: =sum(E29:G31) -> 223.2
A13: 46028 | B13: 384.72 | C13: - | D13: - | E13: - | F13: - | G13: - | J13: 46035 | K13: 10 | L13: - | M13: - | N13: - | O13: - | P13: -
A14: 46029 | B14: - | C14: - | D14: - | E14: - | F14: - | G14: - | J14: 46036 | K14: 57.98 | L14: 34 | M14: - | N14: - | O14: - | P14: -
A16: Semana 3 | J16: Semana 4
A17: Janeiro | J17: Janeiro
A18: 46037 | B18: - | C18: - | D18: - | E18: - | F18: - | G18: - | H18: Saldo da semana | J18: 46044 | K18: - | L18: - | M18: - | N18: - | O18: - | P18: - | Q18: Saldo da semana
A19: 46038 | B19: 40 | C19: - | D19: - | E19: - | F19: - | G19: - | H19: =T10-S10 -> -1047.06 | J19: 46045 | K19: - | L19: - | M19: - | N19: - | O19: - | P19: - | Q19: =T11-S11 -> 0
A20: 46039 | B20: - | C20: - | D20: - | E20: - | F20: - | G20: - | J20: 46046 | K20: - | L20: - | M20: - | N20: - | O20: - | P20: -
A21: 46040 | B21: - | C21: - | D21: - | E21: - | F21: - | G21: - | J21: 46047 | K21: - | L21: - | M21: - | N21: - | O21: - | P21: -
A22: 46041 | B22: 10.4 | C22: 375 | D22: 100 | E22: - | F22: - | G22: - | J22: 46048 | K22: - | L22: - | M22: - | N22: - | O22: - | P22: -
A23: 46042 | B23: 500 | C23: - | D23: - | E23: - | F23: - | G23: - | J23: 46049 | K23: - | L23: - | M23: - | N23: - | O23: - | P23: -
A24: 46043 | B24: 70 | C24: 36.9 | D24: 14.76 | E24: 100 | F24: - | G24: - | J24: 46050 | K24: - | L24: - | M24: - | N24: - | O24: - | P24: -
A27: Semana 5 | J27: Saldo Geral
A28: Janeiro | J28: =sum(H9,H19,H30,Q19,Q9) -> -1766.01
A29: 46051 | B29: - | C29: - | D29: - | E29: - | F29: - | G29: - | H29: Saldo da semana
A30: 46052 | B30: 9.69 | C30: - | D30: - | E30: 111.6 | F30: - | G30: - | H30: =T12-S12 -> 190.85
A31: 46053 | B31: 22.66 | C31: - | D31: - | E31: 111.6 | F31: - | G31: -

Sheet Fevereiro 2026
A6: Semana 1 | J6: Semana 2
A7: Fevereiro | J7: Fevereiro
A8: 46054 | B8: - | C8: - | D8: - | E8: - | F8: - | G8: - | H8: Saldo da semana | J8: 46061 | K8: - | L8: - | M8: - | N8: - | O8: - | P8: - | Q8: Saldo da semana | S8: =SUM(B8:D14) -> 390 | T8: =SUM(E8:G14) -> 0
A9: 46055 | B9: 390 | C9: - | D9: - | E9: - | F9: - | G9: - | H9: =T8-S8 -> -390 | J9: 46062 | K9: 384.72 | L9: 27.98 | M9: - | N9: - | O9: - | P9: - | Q9: =T9-S9 -> -543.19 | S9: =SUM(K8:M14) -> 543.19 | T9: =sum(N8:P14) -> 0
A10: 46056 | B10: - | C10: - | D10: - | E10: - | F10: - | G10: - | J10: 46063 | K10: - | L10: - | M10: - | N10: - | O10: - | P10: - | S10: =sum(B18:D24) -> 183.01 | T10: =sum(E18:G24) -> 0
A11: 46057 | B11: - | C11: - | D11: - | E11: - | F11: - | G11: - | J11: 46064 | K11: - | L11: - | M11: - | N11: - | O11: - | P11: - | S11: =sum(K18:M24) -> 125.06 | T11: =sum(N18:P24) -> 0
A12: 46058 | B12: - | C12: - | D12: - | E12: - | F12: - | G12: - | J12: 46065 | L12: - | M12: - | N12: - | O12: - | P12: - | S12: =sum(B29:D31) -> 0 | T12: =sum(E29:G31) -> 0
A13: 46059 | B13: - | C13: - | D13: - | E13: - | F13: - | G13: - | J13: 46066 | K13: 70 | L13: 12.69 | M13: 47.8 | N13: - | O13: - | P13: -
A14: 46060 | B14: - | C14: - | D14: - | E14: - | F14: - | G14: - | J14: 46067 | K14: - | L14: - | M14: - | N14: - | O14: - | P14: -
A16: Semana 3 | J16: Semana 4
A17: Fevereiro | J17: Fevereiro
A18: 46068 | B18: - | C18: - | D18: - | E18: - | F18: - | G18: - | H18: Saldo da semana | J18: 46075 | K18: - | L18: - | M18: - | N18: - | O18: - | P18: - | Q18: Saldo da semana
A19: 46069 | B19: - | C19: - | D19: - | E19: - | F19: - | G19: - | H19: =T10-S10 -> -183.01 | J19: 46076 | K19: - | L19: - | M19: - | N19: - | O19: - | P19: - | Q19: =T11-S11 -> -125.06
A20: 46070 | B20: - | C20: - | D20: - | E20: - | F20: - | G20: - | J20: 46077 | K20: - | L20: - | M20: - | N20: - | O20: - | P20: -
A21: 46071 | B21: - | C21: - | D21: - | E21: - | F21: - | G21: - | J21: 46078 | K21: - | L21: - | M21: - | N21: - | O21: - | P21: -
A22: 46072 | B22: 145.01 | C22: - | D22: - | E22: - | F22: - | G22: - | J22: 46079 | K22: 20 | L22: 50 | M22: - | N22: - | O22: - | P22: -
A23: 46073 | B23: 38 | C23: - | D23: - | E23: - | F23: - | G23: - | J23: 46080 | K23: 3.66 | L23: - | M23: - | N23: - | O23: - | P23: -
A24: 46074 | B24: - | C24: - | D24: - | E24: - | F24: - | G24: - | J24: 46081 | K24: 51.4 | L24: - | M24: - | N24: - | O24: - | P24: -
J27: Saldo Geral
J28: =sum(H9,H19,H30,Q19,Q9) -> -1241.26

Sheet Março 2026
A6: Semana 1 | J6: Semana 2
A7: Março | J7: Março
A8: 46082 | B8: - | C8: - | D8: - | E8: - | F8: - | G8: - | H8: Saldo da semana | J8: 46089 | K8: - | L8: - | M8: - | N8: - | O8: - | P8: - | Q8: Saldo da semana | S8: =SUM(B8:D14) -> 404 | T8: =SUM(E8:G14) -> 200
A9: 46083 | B9: 375 | C9: - | D9: - | E9: - | F9: - | G9: - | H9: =T8-S8 -> -204 | J9: 46090 | K9: 79.99 | L9: 384.72 | M9: - | N9: - | O9: - | P9: - | Q9: =T9-S9 -> -469.71 | S9: =SUM(K8:M14) -> 469.71 | T9: =sum(N8:P14) -> 0
A10: 46084 | B10: - | C10: - | D10: - | E10: - | F10: - | G10: - | J10: 46091 | K10: - | L10: - | M10: - | N10: - | O10: - | P10: - | S10: =sum(B18:D24) -> 436.46 | T10: =sum(E18:G24) -> 0
A11: 46085 | B11: - | C11: - | D11: - | E11: - | F11: - | G11: - | J11: 46092 | K11: - | L11: - | M11: - | N11: - | O11: - | P11: - | S11: =sum(K18:M24) -> 199.8 | T11: =sum(N18:P24) -> 0
A12: 46086 | B12: 20 | C12: - | D12: - | E12: - | F12: - | G12: - | J12: 46093 | K12: - | L12: - | M12: - | N12: - | O12: - | P12: - | S12: =sum(B29:D31) -> 80 | T12: =sum(E29:G31) -> 0
A13: 46087 | B13: 9 | C13: - | D13: - | E13: 200 | F13: - | G13: - | J13: 46094 | K13: - | L13: - | M13: - | N13: - | O13: - | P13: -
A14: 46088 | B14: - | C14: - | D14: - | E14: - | F14: - | G14: - | J14: 46095 | K14: 5 | L14: - | M14: - | N14: - | O14: - | P14: -
A16: Semana 3 | J16: Semana 4
A17: Março | J17: Março
A18: 46096 | B18: - | C18: - | D18: - | E18: - | F18: - | G18: - | H18: Saldo da semana | J18: 46103 | K18: - | L18: - | M18: - | N18: - | O18: - | P18: - | Q18: Saldo da semana
A19: 46097 | B19: 260 | C19: - | D19: - | E19: - | F19: - | G19: - | H19: =T10-S10 -> -436.46 | J19: 46104 | K19: 67.1 | L19: - | M19: - | N19: - | O19: - | P19: - | Q19: =T11-S11 -> -199.8
A20: 46098 | B20: 3.76 | C20: 130 | D20: - | E20: - | F20: - | G20: - | J20: 46105 | K20: 40.7 | L20: - | M20: - | N20: - | O20: - | P20: -
A21: 46099 | B21: 3.92 | C21: - | D21: - | E21: - | F21: - | G21: - | J21: 46106 | K21: 72 | L21: - | M21: - | N21: - | O21: - | P21: -
A22: 46100 | B22: 38.78 | C22: - | D22: - | E22: - | F22: - | G22: - | J22: 46107 | K22: - | L22: - | M22: - | N22: - | O22: - | P22: -
A23: 46101 | B23: - | C23: - | D23: - | E23: - | F23: - | G23: - | J23: 46108 | K23: 20 | L23: - | M23: - | N23: - | O23: - | P23: -
A24: 46102 | B24: - | C24: - | D24: - | E24: - | F24: - | G24: - | J24: 46109 | K24: - | L24: - | M24: - | N24: - | O24: - | P24: -
A27: Semana 5 | J27: Saldo Geral
A28: Março | J28: =sum(H9,H19,H30,Q19,Q9) -> -1389.97
A29: 46110 | B29: 30 | C29: - | D29: - | E29: - | F29: - | G29: - | H29: Saldo da semana
A30: 46111 | B30: 50 | C30: - | D30: - | E30: - | F30: - | G30: - | H30: =T12-S12 -> -80
A31: 46112 | B31: - | C31: - | D31: - | E31: - | F31: - | G31: -

Sheet Abril 2026
A6: Semana 1 | J6: Semana 2
A7: Abril | J7: Abril
A8: 46113 | B8: 3.84 | C8: - | D8: - | E8: - | F8: - | G8: - | H8: Saldo da semana | J8: 46120 | K8: 5.5 | L8: - | M8: - | N8: - | O8: - | P8: - | Q8: Saldo da semana | S8: =SUM(B8:D14) -> 536.95 | T8: =SUM(E8:G14) -> 150
A9: 46114 | B9: - | C9: - | D9: - | E9: - | F9: - | G9: - | H9: =T8-S8 -> -386.95 | J9: 46121 | K9: 126.25 | L9: - | M9: - | N9: - | O9: - | P9: - | Q9: =T9-S9 -> -391.08 | S9: =SUM(K8:M14) -> 406.08 | T9: =sum(N8:P14) -> 15
A10: 46115 | B10: - | C10: - | D10: - | E10: - | F10: - | G10: - | J10: 46122 | K10: 129.24 | L10: - | M10: - | N10: - | O10: - | P10: - | S10: =sum(B18:D24) -> 562.75 | T10: =sum(E18:G24) -> 0
A11: 46116 | B11: - | C11: - | D11: - | E11: - | F11: - | G11: - | J11: 46123 | K11: - | L11: - | M11: - | N11: - | O11: - | P11: - | S11: =sum(K18:M24) -> 130.61 | T11: =sum(N18:P24) -> 0
A12: 46117 | B12: - | C12: - | D12: - | E12: - | F12: - | G12: - | J12: 46124 | K12: 55.09 | L12: - | M12: - | N12: 15 | O12: - | P12: - | S12: =sum(B29:D30) -> 53.76 | T12: =sum(E29:G30) -> 300
A13: 46118 | B13: 80 | C13: - | D13: - | E13: 150 | F13: - | G13: - | J13: 46125 | K13: 40 | L13: - | M13: - | N13: - | O13: - | P13: -
A14: 46119 | B14: 384.72 | C14: 62.89 | D14: 5.5 | E14: - | F14: - | G14: - | J14: 46126 | K14: 50 | L14: - | M14: - | N14: - | O14: - | P14: -
A16: Semana 3 | J16: Semana 4
A17: Abril | J17: Abril
A18: 46127 | B18: 12.75 | C18: - | D18: - | E18: - | F18: - | G18: - | H18: Saldo da semana | J18: 46134 | K18: 26.77 | L18: - | M18: - | N18: - | O18: - | P18: - | Q18: Saldo da semana
A19: 46128 | B19: 50 | C19: - | D19: - | E19: - | F19: - | G19: - | H19: =T10-S10 -> -562.75 | J19: 46135 | K19: - | L19: - | M19: - | N19: - | O19: - | P19: - | Q19: =T11-S11 -> -130.61
A20: 46129 | B20: - | C20: - | D20: - | E20: - | F20: - | G20: - | J20: 46136 | K20: - | L20: - | M20: - | N20: - | O20: - | P20: -
A21: 46130 | B21: - | C21: - | D21: - | E21: - | F21: - | G21: - | J21: 46137 | K21: 100 | L21: - | M21: - | N21: - | O21: - | P21: -
A22: 46131 | B22: - | C22: - | D22: - | E22: - | F22: - | G22: - | J22: 46138 | K22: - | L22: - | M22: - | N22: - | O22: - | P22: -
A23: 46132 | B23: 500 | C23: - | D23: - | E23: - | F23: - | G23: - | J23: 46139 | K23: - | L23: - | M23: - | N23: - | O23: - | P23: -
A24: 46133 | B24: - | C24: - | D24: - | E24: - | F24: - | G24: - | J24: 46140 | K24: 3.84 | L24: - | M24: - | N24: - | O24: - | P24: -
A27: Semana 5 | J27: Saldo Geral
A28: Abril | J28: =sum(H9,H19,H30,Q19,Q9) -> -1225.15
A29: 46141 | B29: 50 | C29: 3.76 | D29: - | E29: 300 | F29: - | G29: - | H29: Saldo da semana
A30: 46142 | B30: - | C30: - | D30: - | E30: - | F30: - | G30: - | H30: =T12-S12 -> 246.24

Sheet Maio 2026
A6: Semana 1 | J6: Semana 2
A7: Maio | J7: Maio
A8: 46143 | B8: - | C8: - | D8: - | E8: - | F8: - | G8: - | H8: Saldo da semana | J8: 46150 | K8: - | L8: - | M8: - | N8: - | O8: - | P8: - | Q8: Saldo da semana | S8: =SUM(B8:D14) -> 0 | T8: =SUM(E8:G14) -> 0
A9: 46144 | B9: - | C9: - | D9: - | E9: - | F9: - | G9: - | H9: =T8-S8 -> 0 | J9: 46151 | K9: - | L9: - | M9: - | N9: - | O9: - | P9: - | Q9: =T9-S9 -> -423.11 | S9: =SUM(K8:M14) -> 423.11 | T9: =sum(N8:P14) -> 0
A10: 46145 | B10: - | C10: - | D10: - | E10: - | F10: - | G10: - | J10: 46152 | K10: 384.72 | L10: - | M10: - | N10: - | O10: - | P10: - | S10: =sum(B18:D24) -> 761.38 | T10: =sum(E18:G24) -> 30
A11: 46146 | B11: - | C11: - | D11: - | E11: - | F11: - | G11: - | J11: 46153 | K11: 32.89 | L11: - | M11: - | N11: - | O11: - | P11: - | S11: =sum(K18:M24) -> 159.99 | T11: =sum(N18:P24) -> 5.9
A12: 46147 | B12: - | C12: - | D12: - | E12: - | F12: - | G12: - | J12: 46154 | K12: 5.5 | L12: - | M12: - | N12: - | O12: - | P12: - | S12: =sum(B29:D31) -> 0 | T12: =sum(E29:G31) -> 0
A13: 46148 | B13: - | C13: - | D13: - | E13: - | F13: - | G13: - | J13: 46155 | K13: - | L13: - | M13: - | N13: - | O13: - | P13: -
A14: 46149 | B14: - | C14: - | D14: - | E14: - | F14: - | G14: - | J14: 46156 | K14: - | L14: - | M14: - | N14: - | O14: - | P14: -
A16: Semana 3 | J16: Semana 4
A17: Maio | J17: Maio
A18: 46157 | B18: - | C18: - | D18: - | E18: - | F18: - | G18: - | H18: Saldo da semana | J18: 46164 | K18: - | L18: - | M18: - | N18: - | O18: - | P18: - | Q18: Saldo da semana
A19: 46158 | B19: - | C19: - | D19: - | E19: - | F19: - | G19: - | H19: =T10-S10 -> -731.38 | J19: 46165 | K19: - | L19: - | M19: - | N19: - | O19: - | P19: - | Q19: =T11-S11 -> -154.09
A20: 46159 | B20: 59.57 | C20: - | D20: - | E20: - | F20: - | G20: - | J20: 46166 | K20: - | L20: - | M20: - | N20: - | O20: - | P20: -
A21: 46160 | B21: 20 | C21: 34 | D21: - | E21: - | F21: - | G21: - | J21: 46167 | K21: - | L21: - | M21: - | N21: - | O21: - | P21: -
A22: 46161 | B22: 8.6 | C22: - | D22: - | E22: - | F22: - | G22: - | J22: 46168 | K22: 100 | L22: 50 | M22: - | N22: - | O22: - | P22: -
A23: 46162 | B23: 474 | C23: 20.97 | D23: 4.24 | E23: - | F23: - | G23: - | J23: 46169 | K23: 4 | L23: - | M23: - | N23: - | O23: - | P23: -
A24: 46163 | B24: 140 | C24: - | D24: - | E24: 30 | F24: - | G24: - | J24: 46170 | K24: 5.99 | L24: - | M24: - | N24: 5.9 | O24: - | P24: -
A27: Semana 5 | J27: Saldo Geral
A28: Maio | J28: =sum(H9,H19,H30,Q19,Q9) -> -1308.58
A29: 46171 | B29: - | C29: - | D29: - | E29: - | F29: - | G29: - | H29: Saldo da semana
A30: 46172 | B30: - | C30: - | D30: - | E30: - | F30: - | G30: - | H30: =T12-S12 -> 0
A31: 46173 | B31: - | C31: - | D31: - | E31: - | F31: - | G31: -

Sheet Junho 2026
A6: Semana 1 | J6: Semana 2
A7: Junho | J7: Junho
A8: 46174 | B8: 10.75 | C8: - | D8: - | E8: 24 | F8: - | G8: - | H8: Saldo da semana | J8: 46181 | K8: - | L8: - | M8: - | N8: - | O8: - | P8: - | Q8: Saldo da semana | S8: =SUM(B8:D14) -> 176.1 | T8: =SUM(E8:G14) -> 71.08
A9: 46175 | B9: - | C9: - | D9: - | E9: - | F9: - | G9: - | H9: =T8-S8 -> -105.02 | J9: 46182 | K9: - | L9: - | M9: - | N9: - | O9: - | P9: - | Q9: =T9-S9 -> 0 | S9: =SUM(K8:M14) -> 0 | T9: =sum(N8:P14) -> 0
A10: 46176 | B10: 50 | C10: - | D10: - | E10: - | F10: - | G10: - | J10: 46183 | K10: - | L10: - | M10: - | N10: - | O10: - | P10: - | S10: =sum(B18:D24) -> 0 | T10: =sum(E18:G24) -> 0
A11: 46177 | B11: 115.35 | C11: - | D11: - | E11: 15.08 | F11: - | G11: - | J11: 46184 | K11: - | L11: - | M11: - | N11: - | O11: - | P11: - | S11: =sum(K18:M24) -> 0 | T11: =sum(N18:P24) -> 0
A12: 46178 | B12: - | C12: - | D12: - | E12: - | F12: - | G12: - | J12: 46185 | K12: - | L12: - | M12: - | N12: - | O12: - | P12: - | S12: =sum(B29:D30) -> 0 | T12: =sum(E29:G30) -> 0
A13: 46179 | B13: - | C13: - | D13: - | E13: 32 | F13: - | G13: - | J13: 46186 | K13: - | L13: - | M13: - | N13: - | O13: - | P13: -
A14: 46180 | B14: - | C14: - | D14: - | E14: - | F14: - | G14: - | J14: 46187 | K14: - | L14: - | M14: - | N14: - | O14: - | P14: -
A16: Semana 3 | J16: Semana 4
A17: Junho | J17: Junho
A18: 46188 | B18: - | C18: - | D18: - | E18: - | F18: - | G18: - | H18: Saldo da semana | J18: 46195 | K18: - | L18: - | M18: - | N18: - | O18: - | P18: - | Q18: Saldo da semana
A19: 46189 | B19: - | C19: - | D19: - | E19: - | F19: - | G19: - | H19: =T10-S10 -> 0 | J19: 46196 | K19: - | L19: - | M19: - | N19: - | O19: - | P19: - | Q19: =T11-S11 -> 0
A20: 46190 | B20: - | C20: - | D20: - | E20: - | F20: - | G20: - | J20: 46197 | K20: - | L20: - | M20: - | N20: - | O20: - | P20: -
A21: 46191 | B21: - | C21: - | D21: - | E21: - | F21: - | G21: - | J21: 46198 | K21: - | L21: - | M21: - | N21: - | O21: - | P21: -
A22: 46192 | B22: - | C22: - | D22: - | E22: - | F22: - | G22: - | J22: 46199 | K22: - | L22: - | M22: - | N22: - | O22: - | P22: -
A23: 46193 | B23: - | C23: - | D23: - | E23: - | F23: - | G23: - | J23: 46200 | K23: - | L23: - | M23: - | N23: - | O23: - | P23: -
A24: 46194 | B24: - | C24: - | D24: - | E24: - | F24: - | G24: - | J24: 46201 | K24: - | L24: - | M24: - | N24: - | O24: - | P24: -
A27: Semana 5 | J27: Saldo Geral
A28: Junho | J28: =sum(H9,H19,H30,Q19,Q9) -> -105.02
A29: 46202 | B29: - | C29: - | D29: - | E29: - | F29: - | G29: - | H29: Saldo da semana
A30: 46203 | B30: - | C30: - | D30: - | E30: - | F30: - | G30: - | H30: =T12-S12 -> 0

Sheet Julho 2026
A6: Semana 1 | J6: Semana 2
A7: Junho | J7: Junho
A8: 46174 | B8: - | C8: - | D8: - | E8: - | F8: - | G8: - | H8: Saldo da semana | J8: 46030 | K8: - | L8: - | M8: - | N8: - | O8: - | P8: - | Q8: Saldo da semana | S8: =SUM(B8:D14) -> 0 | T8: =SUM(E8:G14) -> 0
A9: 46175 | B9: - | C9: - | D9: - | E9: - | F9: - | G9: - | H9: =T8-S8 -> 0 | J9: 46031 | K9: - | L9: - | M9: - | N9: - | O9: - | P9: - | Q9: =T9-S9 -> 0 | S9: =SUM(K8:M14) -> 0 | T9: =sum(N8:P14) -> 0
A10: 46176 | B10: - | C10: - | D10: - | E10: - | F10: - | G10: - | J10: 46032 | K10: - | L10: - | M10: - | N10: - | O10: - | P10: - | S10: =sum(B18:D24) -> 0 | T10: =sum(E18:G24) -> 0
A11: 46177 | B11: - | C11: - | D11: - | E11: - | F11: - | G11: - | J11: 46033 | K11: - | L11: - | M11: - | N11: - | O11: - | P11: - | S11: =sum(K18:M24) -> 0 | T11: =sum(N18:P24) -> 0
A12: 46178 | B12: - | C12: - | D12: - | E12: - | F12: - | G12: - | J12: 46034 | K12: - | L12: - | M12: - | N12: - | O12: - | P12: - | S12: =sum(B29:D31) -> 0 | T12: =sum(E29:G31) -> 0
A13: 46179 | B13: - | C13: - | D13: - | E13: - | F13: - | G13: - | J13: 46035 | K13: - | L13: - | M13: - | N13: - | O13: - | P13: -
A14: 46180 | B14: - | C14: - | D14: - | E14: - | F14: - | G14: - | J14: 46036 | K14: - | L14: - | M14: - | N14: - | O14: - | P14: -
A16: Semana 3 | J16: Semana 4
A17: Junho | J17: Junho
A18: 46037 | B18: - | C18: - | D18: - | E18: - | F18: - | G18: - | H18: Saldo da semana | J18: 46044 | K18: - | L18: - | M18: - | N18: - | O18: - | P18: - | Q18: Saldo da semana
A19: 46038 | B19: - | C19: - | D19: - | E19: - | F19: - | G19: - | H19: =T10-S10 -> 0 | J19: 46045 | K19: - | L19: - | M19: - | N19: - | O19: - | P19: - | Q19: =T11-S11 -> 0
A20: 46039 | B20: - | C20: - | D20: - | E20: - | F20: - | G20: - | J20: 46046 | K20: - | L20: - | M20: - | N20: - | O20: - | P20: -
A21: 46040 | B21: - | C21: - | D21: - | E21: - | F21: - | G21: - | J21: 46047 | K21: - | L21: - | M21: - | N21: - | O21: - | P21: -
A22: 46041 | B22: - | C22: - | D22: - | E22: - | F22: - | G22: - | J22: 46048 | K22: - | L22: - | M22: - | N22: - | O22: - | P22: -
A23: 46042 | B23: - | C23: - | D23: - | E23: - | F23: - | G23: - | J23: 46049 | K23: - | L23: - | M23: - | N23: - | O23: - | P23: -
A24: 46043 | B24: - | C24: - | D24: - | E24: - | F24: - | G24: - | J24: 46050 | K24: - | L24: - | M24: - | N24: - | O24: - | P24: -
A27: Semana 5 | J27: Saldo Geral
A28: Junho | J28: =sum(H9,H19,H30,Q19,Q9) -> 0
A29: 46051 | B29: - | C29: - | D29: - | E29: - | F29: - | G29: - | H29: Saldo da semana
A30: 46052 | B30: - | C30: - | D30: - | E30: - | F30: - | G30: - | H30: =T12-S12 -> 0
A31: 46053 | B31: - | C31: - | D31: - | E31: - | F31: - | G31: -

Sheet Abril 2025
A6: Mês | B6: Semana | C6: Saida | D6: Meio | E6: Informação | M6: Mês | N6: Semana | O6: Entrada | P6: Meio | Q6: Informação
A7: 45748 | B7: Terça-feira | C7: - | D7: - | E7: - | G7: =K9-K8 -> 1148.67 | H7: Pix | I7: Dinheiro F | J7: Cartão | K7: Total | M7: 45748 | N7: Terça-feira | O7: - | P7: - | Q7: -
A8: 45749 | B8: quarta-feira | C8: 132.98 | D8: Pix | E8: Presente Gustavo | G8: Despesas | H8: =SUMIF(D7:D41,"Pix",C7:C41) -> 832.98 | I8: =SUMIF(D7:D41,"Dinheiro F",C7:C41) -> 88 | J8: =SUMIF(D7:D41,"Cartão",C7:C41) -> 444.35 | K8: =SUM(H8:J8) -> 1365.33 | M8: 45749 | N8: quarta-feira | O8: - | P8: - | Q8: -
A9: 45750 | B9: quinta-feira | C9: 49.98 | D9: Cartão | E9: Calça Moletom | G9: Receita | H9: =SUMIF(P7:P41,"Pix",O7:O41) -> 150 | I9: =SUMIF(P7:P41,"Dinheiro F",O7:O41) -> 230 | J9: =SUMIF(P7:P41,"Cartão",O7:O41) -> 2134 | K9: =SUM(H9:J9) -> 2514 | M9: 45750 | N9: quinta-feira | O9: 150 | P9: Dinheiro F | Q9: Estoque
A10: 45751 | B10: sexta-feira | C10: - | D10: - | E10: - | M10: 45751 | N10: sexta-feira | O10: 150 | P10: Pix | Q10: Limpeza Marquize
A11: 45752 | B11: sábado | C11: 37.99 | D11: Cartão | E11: Camisa Uv | M11: 45752 | N11: sábado | O11: 20 | P11: Dinheiro F | Q11: Bonificação
A12: 45753 | B12: domingo | C12: 500 | D12: Pix | E12: Aluguel | M12: 45753 | N12: domingo | O12: - | P12: - | Q12: -
A13: 45753 | B13: domingo | C13: 23.18 | D13: Cartão | E13: Sorvete Mãe | M13: 45753 | N13: domingo | O13: - | P13: - | Q13: -
A14: 45754 | B14: segunda-feira | C14: - | D14: - | E14: - | M14: 45754 | N14: segunda-feira | O14: - | P14: - | Q14: -
A15: 45755 | B15: terça-feira | C15: - | D15: - | E15: - | M15: 45755 | N15: terça-feira | O15: - | P15: - | Q15: -
A16: 45756 | B16: quarta-feira | C16: - | D16: - | E16: - | M16: 45756 | N16: quarta-feira | O16: - | P16: - | Q16: -
A17: 45757 | B17: quinta-feira | C17: - | D17: - | E17: - | M17: 45757 | N17: quinta-feira | O17: - | P17: - | Q17: -
A18: 45758 | B18: sexta-feira | C18: - | D18: - | E18: - | M18: 45758 | N18: sexta-feira | O18: - | P18: - | Q18: -
A19: 45759 | B19: sábado | C19: 62 | D19: Cartão | E19: Uber Gustavo | M19: 45759 | N19: sábado | O19: 20 | P19: Dinheiro F | Q19: Bonificação
A20: 45759 | B20: sábado | C20: 100 | D20: Pix | E20: Pizza (Mãe) | M20: 45759 | N20: sábado | O20: - | P20: - | Q20: -
A21: 45760 | B21: domingo | C21: 43.32 | D21: Cartão | E21: Sorvete | M21: 45760 | N21: domingo | O21: - | P21: - | Q21: -
A22: 45761 | B22: segunda-feira | C22: - | D22: - | E22: - | M22: 45761 | N22: segunda-feira | O22: - | P22: - | Q22: -
A23: 45762 | B23: terça-feira | C23: - | D23: - | E23: - | M23: 45762 | N23: terça-feira | O23: - | P23: - | Q23: -
A24: 45763 | B24: quarta-feira | C24: 18.5 | D24: Dinheiro F | E24: Lanches | M24: 45763 | N24: quarta-feira | O24: 632 | P24: Cartão | Q24: Adiantamento
A25: 45764 | B25: quinta-feira | C25: - | D25: - | E25: - | M25: 45764 | N25: quinta-feira | O25: - | P25: - | Q25: -
A26: 45765 | B26: sexta-feira | C26: 47 | D26: Dinheiro F | E26: Sorvete | M26: 45765 | N26: sexta-feira | O26: - | P26: - | Q26: -
A27: 45766 | B27: sábado | C27: - | D27: - | E27: - | M27: 45766 | N27: sábado | O27: 20 | P27: Dinheiro F | Q27: Bonificação
A28: 45767 | B28: domingo | C28: - | D28: - | E28: - | M28: 45767 | N28: domingo | O28: - | P28: - | Q28: -
A29: 45768 | B29: segunda-feira | C29: 50.95 | D29: Cartão | E29: Chocolates | M29: 45768 | N29: segunda-feira | O29: - | P29: - | Q29: -
A30: 45769 | B30: terça-feira | C30: 14 | D30: Dinheiro F | E30: Lanches | M30: 45769 | N30: terça-feira | O30: - | P30: - | Q30: -
A31: 45770 | B31: quarta-feira | C31: 107 | D31: Cartão | E31: Geladeira | M31: 45770 | N31: quarta-feira | O31: - | P31: - | Q31: -
A32: 45771 | B32: quinta-feira | C32: 50 | D32: Pix | E32: Mãe | M32: 45771 | N32: quinta-feira | O32: - | P32: - | Q32: -
A33: 45772 | B33: sexta-feira | C33: - | D33: - | E33: - | M33: 45772 | N33: sexta-feira | O33: - | P33: - | Q33: -
A34: 45773 | B34: sábado | C34: 8.5 | D34: Dinheiro F | E34: Lanches | M34: 45773 | N34: sábado | O34: 20 | P34: Dinheiro F | Q34: Bonificação
A35: 45774 | B35: domingo | C35: 55.79 | D35: Cartão | E35: Sorvete | M35: 45774 | N35: domingo | O35: - | P35: - | Q35: -
A36: 45775 | B36: segunda-feira | C36: - | D36: - | E36: - | M36: 45775 | N36: segunda-feira | O36: - | P36: - | Q36: -
A37: 45776 | B37: terça-feira | C37: 14.14 | D37: Cartão | E37: Pão e Forma e suco | M37: 45776 | N37: terça-feira | O37: 1502 | P37: Cartão | Q37: Salário
A38: 45777 | B38: quarta-feira | C38: 50 | D38: Pix | E38: Mãe | M38: 45777 | N38: quarta-feira | O38: - | P38: - | Q38: -

Sheet Maio 2025
A6: Mês | B6: Semana | C6: Saida | D6: Meio | E6: Informação | M6: Mês | N6: Semana | O6: Entrada | P6: Meio | Q6: Informação
A7: 45778 | B7: Quinta-feira | C7: - | D7: - | E7: - | G7: =K9-K8 -> 673.88 | H7: Pix | I7: Dinheiro F | J7: Cartão | K7: Total | M7: 45778 | N7: Quinta-feira | O7: - | P7: - | Q7: -
A8: 45779 | B8: sexta-feira | C8: - | D8: - | E8: - | G8: Despesas | H8: =SUMIF(D7:D41,"Pix",C7:C41) -> 1242.97 | I8: =SUMIF(D7:D41,"Dinheiro F",C7:C41) -> 274.65 | J8: =SUMIF(D7:D41,"Cartão",C7:C41) -> 137.5 | K8: =SUM(H8:J8) -> 1655.12 | M8: 45779 | N8: sexta-feira | O8: - | P8: - | Q8: -
A9: 45780 | B9: sábado | C9: - | D9: - | E9: - | G9: Receita | H9: =SUMIF(P7:P41,"Pix",O7:O41) -> 0 | I9: =SUMIF(P7:P41,"Dinheiro F",O7:O41) -> 230 | J9: =SUMIF(P7:P41,"Cartão",O7:O41) -> 2099 | K9: =SUM(H9:J9) -> 2329 | M9: 45780 | N9: sábado | O9: 20 | P9: Dinheiro F | Q9: Bonificação
A10: 45781 | B10: domingo | C10: 25.5 | D10: Pix | E10: Sorvete | M10: 45781 | N10: domingo | O10: - | P10: - | Q10: -
A11: 45782 | B11: segunda-feira | C11: 500 | D11: Pix | E11: Aluguel | M11: 45782 | N11: segunda-feira | O11: - | P11: - | Q11: -
A12: 45783 | B12: terça-feira | C12: 107 | D12: Dinheiro F | E12: Geladeira | M12: 45783 | N12: terça-feira | O12: - | P12: - | Q12: -
A13: 45784 | B13: quarta-feira | C13: 80 | D13: Cartão | E13: Internet | M13: 45784 | N13: quarta-feira | O13: - | P13: - | Q13: -
A14: 45785 | B14: quinta-feira | C14: 384.7 | D14: Pix | E14: Estácio | M14: 45785 | N14: quinta-feira | O14: 150 | P14: Dinheiro F | Q14: Estoque
A15: 45786 | B15: sexta-feira | C15: 7 | D15: Dinheiro F | E15: Refrigerante | M15: 45786 | N15: sexta-feira | O15: - | P15: - | Q15: -
A16: 45786 | B16: sexta-feira | C16: 84.53 | D16: Pix | E16: Presente mãe | M16: 45786 | N16: sexta-feira | O16: - | P16: - | Q16: -
A17: 45787 | B17: sábado | C17: 85.5 | D17: Pix | E17: Passagens, sorvete, lanches | M17: 45787 | N17: sábado | O17: 20 | P17: Dinheiro F | Q17: Bonificação
A18: 45788 | B18: domingo | C18: - | D18: - | E18: - | M18: 45788 | N18: domingo | O18: - | P18: - | Q18: -
A19: 45789 | B19: segunda-feira | C19: 132.74 | D19: Pix | E19: Carteira Definitiva | M19: 45789 | N19: segunda-feira | O19: - | P19: - | Q19: -
A20: 45790 | B20: terça-feira | C20: 46.5 | D20: Dinheiro F | E20: Sorvete | M20: 45790 | N20: terça-feira | O20: - | P20: - | Q20: -
A21: 45791 | B21: quarta-feira | C21: - | D21: - | E21: - | M21: 45791 | N21: quarta-feira | O21: - | P21: - | Q21: -
A22: 45792 | B22: quinta-feira | C22: 30 | D22: Pix | E22: Almoço | M22: 45792 | N22: quinta-feira | O22: - | P22: - | Q22: -
A23: 45793 | B23: sexta-feira | C23: 21 | D23: Dinheiro F | E23: Escova de Dente | M23: 45793 | N23: sexta-feira | O23: 679 | P23: Cartão | Q23: Adiantamento
A24: 45794 | B24: sábado | C24: - | D24: - | E24: - | M24: 45794 | N24: sábado | O24: 20 | P24: Dinheiro F | Q24: Bonificação
A25: 45795 | B25: domingo | C25: - | D25: - | E25: - | M25: 45795 | N25: domingo | O25: - | P25: - | Q25: -
A26: 45796 | B26: segunda-feira | C26: - | D26: - | E26: - | M26: 45796 | N26: segunda-feira | O26: - | P26: - | Q26: -
A27: 45797 | B27: terça-feira | C27: 5 | D27: Dinheiro F | E27: Presente Edmar | M27: 45797 | N27: terça-feira | O27: - | P27: - | Q27: -
A28: 45798 | B28: quarta-feira | C28: 34.15 | D28: Dinheiro F | E28: Remédios | M28: 45798 | N28: quarta-feira | O28: - | P28: - | Q28: -
A29: 45799 | B29: quinta-feira | C29: 57.5 | D29: Cartão | E29: Supermercado | M29: 45799 | N29: quinta-feira | O29: - | P29: - | Q29: -
A30: 45800 | B30: sexta-feira | C30: - | D30: - | E30: - | M30: 45800 | N30: sexta-feira | O30: - | P30: - | Q30: -
A31: 45801 | B31: sábado | C31: 8.5 | D31: Dinheiro F | E31: Lanches | M31: 45801 | N31: sábado | O31: - | P31: - | Q31: -
A32: 45802 | B32: domingo | C32: 25 | D32: Dinheiro F | E32: Sorvete | M32: 45802 | N32: domingo | O32: - | P32: - | Q32: -
A33: 45803 | B33: segunda-feira | C33: - | D33: - | E33: - | M33: 45803 | N33: segunda-feira | O33: - | P33: - | Q33: -
A34: 45804 | B34: terça-feira | C34: 6 | D34: Dinheiro F | E34: Refrigerante | M34: 45804 | N34: terça-feira | O34: - | P34: - | Q34: -
A35: 45805 | B35: quarta-feira | C35: 14.5 | D35: Dinheiro F | E35: Lanches | M35: 45805 | N35: quarta-feira | O35: - | P35: - | Q35: -
A36: 45806 | B36: quinta-feira | C36: - | D36: - | E36: - | M36: 45806 | N36: quinta-feira | O36: 1420 | P36: Cartão | Q36: Salário
A37: 45807 | B37: sexta-feira | C37: - | D37: - | E37: - | M37: 45807 | N37: sexta-feira | O37: - | P37: - | Q37: -
A38: 45808 | B38: sábado | C38: - | D38: - | E38: - | M38: 45808 | N38: sábado | O38: 20 | P38: Dinheiro F | Q38: Bonificação

Sheet Junho 2025
A6: Mês | B6: Semana | C6: Saida | D6: Meio | E6: Informação | M6: Mês | N6: Semana | O6: Entrada | P6: Meio | Q6: Informação
A7: 45809 | B7: domingo | C7: - | D7: - | E7: - | G7: =K9-K8 -> -2273.91 | H7: Pix | I7: Dinheiro F | J7: Cartão | K7: Total | M7: 45809 | N7: domingo | O7: - | P7: - | Q7: -
A8: 45810 | B8: segunda-feira | C8: 24 | D8: Pix | E8: Lanche Acumulado | G8: Despesas | H8: =SUMIF(D7:D39,"Pix",C7:C39) -> 4261.98 | I8: =SUMIF(D7:D39,"Dinheiro F",C7:C39) -> 151 | J8: =SUMIF(D7:D39,"Cartão",C7:C39) -> 227.93 | K8: =SUM(H8:J8) -> 4640.91 | M8: 45810 | N8: segunda-feira | O8: 150 | P8: Dinheiro F | Q8: Estoque
A9: 45811 | B9: terça-feira | C9: 20 | D9: Pix | E9: Mãe | G9: Receita | H9: =SUMIF(P7:P39,"Pix",O7:O39) -> 0 | I9: =SUMIF(P7:P39,"Dinheiro F",O7:O39) -> 330 | J9: =SUMIF(P7:P39,"Cartão",O7:O39) -> 2037 | K9: =SUM(H9:J9) -> 2367 | M9: 45811 | N9: terça-feira | O9: - | P9: - | Q9: -
A10: 45812 | B10: quarta-feira | C10: - | D10: - | E10: - | M10: 45812 | N10: quarta-feira | O10: - | P10: - | Q10: -
A11: 45813 | B11: quinta-feira | C11: 500 | D11: Pix | E11: Aluguel | M11: 45813 | N11: quinta-feira | O11: - | P11: - | Q11: -
A12: 45814 | B12: sexta-feira | C12: - | D12: - | E12: - | M12: 45814 | N12: sexta-feira | O12: - | P12: - | Q12: -
A13: 45815 | B13: sábado | C13: 6 | D13: Pix | E13: Lanche | M13: 45815 | N13: sábado | O13: 20 | P13: Dinheiro F | Q13: Bonificação
A14: 45816 | B14: domingo | C14: 24 | D14: Pix | E14: Sorvete | M14: 45816 | N14: domingo | O14: - | P14: - | Q14: -
A15: 45817 | B15: segunda-feira | C15: - | D15: - | E15: - | M15: 45817 | N15: segunda-feira | O15: - | P15: - | Q15: -
A16: 45818 | B16: terça-feira | C16: - | D16: - | E16: - | M16: 45818 | N16: terça-feira | O16: - | P16: - | Q16: -
A17: 45819 | B17: quarta-feira | C17: 19 | D17: Pix | E17: Chocolates | M17: 45819 | N17: quarta-feira | O17: - | P17: - | Q17: -
A18: 45820 | B18: quinta-feira | C18: 18.98 | D18: Pix | E18: Chocolates | M18: 45820 | N18: quinta-feira | O18: - | P18: - | Q18: -
A19: 45821 | B19: sexta-feira | C19: - | D19: - | E19: - | M19: 45821 | N19: sexta-feira | O19: - | P19: - | Q19: -
A20: 45822 | B20: sábado | C20: 79.99 | D20: Cartão | E20: Internet | M20: 45822 | N20: sábado | O20: 20 | P20: Dinheiro F | Q20: Bonificação
A21: 45823 | B21: domingo | C21: 32 | D21: Dinheiro F | E21: Sanduiche | M21: 45823 | N21: domingo | O21: - | P21: - | Q21: -
A22: 45824 | B22: segunda-feira | C22: 20.97 | D22: Cartão | E22: Pasta de Dente | M22: 45824 | N22: segunda-feira | O22: 679 | P22: Cartão | Q22: Adiantamento
A23: 45825 | B23: terça-feira | C23: 2.5 | D23: Dinheiro F | E23: Pão de Queijo | M23: 45825 | N23: terça-feira | O23: - | P23: - | Q23: -
A24: 45826 | B24: quarta-feira | C24: 6 | D24: Pix | E24: Salgado | M24: 45826 | N24: quarta-feira | O24: - | P24: - | Q24: -
A25: 45827 | B25: quinta-feira | C25: 100 | D25: Dinheiro F | E25: Mãe | M25: 45827 | N25: quinta-feira | O25: - | P25: - | Q25: -
A26: 45828 | B26: sexta-feira | C26: - | D26: - | E26: - | M26: 45828 | N26: sexta-feira | O26: - | P26: - | Q26: -
A27: 45829 | B27: sábado | C27: 28 | D27: Cartão | E27: Almoço | M27: 45829 | N27: sábado | O27: 20 | P27: Dinheiro F | Q27: Bonificação
A28: 45830 | B28: domingo | C28: 40 | D28: Cartão | E28: Sorvete | M28: 45830 | N28: domingo | O28: - | P28: - | Q28: -
A29: 45831 | B29: segunda-feira | C29: 36 | D29: Pix | E29: Mãe | M29: 45831 | N29: segunda-feira | O29: - | P29: - | Q29: -
A30: 45832 | B30: terça-feira | C30: 58.97 | D30: Cartão | E30: Desodorante | M30: 45832 | N30: terça-feira | O30: - | P30: - | Q30: -
A31: 45833 | B31: quarta-feira | C31: 3580 | D31: Pix | E31: Computador (Metade) | M31: 45833 | N31: quarta-feira | O31: - | P31: - | Q31: -
A32: 45834 | B32: quinta-feira | C32: 2.5 | D32: Dinheiro F | E32: Pão de Queijo | M32: 45834 | N32: quinta-feira | O32: 1358 | P32: Cartão | Q32: Salário
A33: 45835 | B33: sexta-feira | C33: - | D33: - | E33: - | M33: 45835 | N33: sexta-feira | O33: - | P33: - | Q33: -
A34: 45836 | B34: sábado | C34: 14 | D34: Dinheiro F | E34: Refrigerante | M34: 45836 | N34: sábado | O34: 20 | P34: Dinheiro F | Q34: Bonificação
A35: 45837 | B35: domingo | C35: - | D35: - | E35: - | M35: 45837 | N35: domingo | O35: - | P35: - | Q35: -
A36: 45838 | B36: segunda-feira | C36: 28 | D36: Pix | E36: Almoço | M36: 45838 | N36: segunda-feira | O36: 100 | P36: Dinheiro F | Q36: Free lancer

Sheet Julho 2025
A6: Mês | B6: Semana | C6: Saida | D6: Meio | E6: Informação | M6: Mês | N6: Semana | O6: Entrada | P6: Meio | Q6: Informação
A7: 45839 | B7: terça-feira | C7: - | D7: - | E7: - | G7: =K9-K8 -> 8332.94 | H7: Pix | I7: Dinheiro F | J7: Cartão | K7: Total | M7: 45839 | N7: terça-feira | O7: - | P7: - | Q7: -
A8: 45840 | B8: quarta-feira | C8: - | D8: - | E8: - | G8: Despesas | H8: =SUMIF(D7:D39,"Pix",C7:C39) -> 980.15 | I8: =SUMIF(D7:D39,"Dinheiro F",C7:C39) -> 0 | J8: =SUMIF(D7:D39,"Cartão",C7:C39) -> 149.7 | K8: =SUM(H8:J8) -> 1129.85 | M8: 45840 | N8: quarta-feira | O8: 100 | P8: Dinheiro F | Q8: Free lancer
A9: 45841 | B9: quinta-feira | C9: 88 | D9: Pix | E9: Lanches, sorvete | G9: Receita | H9: =SUMIF(P7:P39,"Pix",O7:O39) -> 0 | I9: =SUMIF(P7:P39,"Dinheiro F",O7:O39) -> 100 | J9: =SUMIF(P7:P39,"Cartão",O7:O39) -> 9362.79 | K9: =SUM(H9:J9) -> 9462.79 | M9: 45841 | N9: quinta-feira | O9: - | P9: - | Q9: -
A10: 45842 | B10: sexta-feira | C10: - | D10: - | E10: - | M10: 45842 | N10: sexta-feira | O10: - | P10: - | Q10: -
A11: 45843 | B11: sábado | C11: - | D11: - | E11: - | M11: 45843 | N11: sábado | O11: - | P11: - | Q11: -
A12: 45844 | B12: domingo | C12: 46 | D12: Cartão | E12: Sorvete | M12: 45844 | N12: domingo | O12: - | P12: - | Q12: -
A13: 45845 | B13: segunda-feira | C13: - | D13: - | E13: - | M13: 45845 | N13: segunda-feira | O13: - | P13: - | Q13: -
A14: 45846 | B14: terça-feira | C14: - | D14: - | E14: - | M14: 45846 | N14: terça-feira | O14: - | P14: - | Q14: -
A15: 45847 | B15: quarta-feira | C15: 49.99 | D15: Cartão | E15: Internet & Crunchyroll | M15: 45847 | N15: quarta-feira | O15: - | P15: - | Q15: -
A16: 45848 | B16: quinta-feira | C16: 20.69 | D16: Pix | E16: Teatro dos finais infelizes | M16: 45848 | N16: quinta-feira | O16: - | P16: - | Q16: -
A17: 45849 | B17: sexta-feira | C17: 30 | D17: Pix | E17: Plano de vida | M17: 45849 | N17: sexta-feira | O17: 5291.79 | P17: Cartão | Q17: Acerto
A18: 45850 | B18: sábado | C18: - | D18: - | E18: - | M18: 45850 | N18: sábado | O18: - | P18: - | Q18: -
A19: 45851 | B19: domingo | C19: 14 | D19: Pix | E19: Porta Copos | M19: 45851 | N19: domingo | O19: - | P19: - | Q19: -
A20: 45852 | B20: segunda-feira | C20: 30 | D20: Pix | E20: Corte de cabelo | M20: 45852 | N20: segunda-feira | O20: - | P20: - | Q20: -
A21: 45853 | B21: terça-feira | C21: 85.86 | D21: Pix | E21: Ida a Estacio | M21: 45853 | N21: terça-feira | O21: - | P21: - | Q21: -
A22: 45854 | B22: quarta-feira | C22: 100 | D22: Pix | E22: Mãe | M22: 45854 | N22: quarta-feira | O22: - | P22: - | Q22: -
A23: 45855 | B23: quinta-feira | C23: - | D23: - | E23: - | M23: 45855 | N23: quinta-feira | O23: - | P23: - | Q23: -
A24: 45856 | B24: sexta-feira | C24: - | D24: - | E24: - | M24: 45856 | N24: sexta-feira | O24: - | P24: - | Q24: -
A25: 45857 | B25: sábado | C25: 500 | D25: Pix | E25: Aluguel | M25: 45857 | N25: sábado | O25: - | P25: - | Q25: -
A26: 45858 | B26: domingo | C26: 53.71 | D26: Cartão | E26: Sorvete / Pães | M26: 45858 | N26: domingo | O26: - | P26: - | Q26: -
A27: 45859 | B27: segunda-feira | C27: 11.6 | D27: Pix | E27: Metrô | M27: 45859 | N27: segunda-feira | O27: - | P27: - | Q27: -
A28: 45860 | B28: terça-feira | C28: - | D28: - | E28: - | M28: 45860 | N28: terça-feira | O28: 4071 | P28: Cartão | Q28: Multa recisória
A29: 45861 | B29: quarta-feira | C29: - | D29: - | E29: - | M29: 45861 | N29: quarta-feira | O29: - | P29: - | Q29: -
A30: 45862 | B30: quinta-feira | C30: - | D30: - | E30: - | M30: 45862 | N30: quinta-feira | O30: - | P30: - | Q30: -
A31: 45863 | B31: sexta-feira | C31: 50 | D31: Pix | E31: TG | M31: 45863 | N31: sexta-feira | O31: - | P31: - | Q31: -
A32: 45864 | B32: sábado | C32: 50 | D32: Pix | E32: Mãe | M32: 45864 | N32: sábado | O32: - | P32: - | Q32: -
A33: 45865 | B33: domingo | C33: - | D33: - | E33: - | M33: 45865 | N33: domingo | O33: - | P33: - | Q33: -
